Workbook

Sheet codebook_short
A1: Pillar | B1: Indicator Name | C1: Programmatic Name | D1: Code | E1: Description | F1: Unit | G1: Source
A2: Talk | B2: Count of words in reporting relating to Poverty and Wellbeing | C2: talk_wb_count | D2: T001 | E2: The total number of references to selected keywords in Annual Reporting, Sustainability Reports and Websites; in this case related to Poverty & Wellbeing. | F2: Count | G2: Annual Reports, Sustainability Reports and Company Websites
A3: Talk | B3: Count of words in reporting relating to Education and Skills | C3: talk_skills_count | D3: T002 | E3: The total number of references to selected keywords in Annual Reporting, Sustainability Reports and Websites; in this case related to Education & Skills | F3: Count | G3: Annual Reports, Sustainability Reports and Company Websites
A4: Talk | B4: Count of words in reporting relating to Equality | C4: talk_equality_count | D4: T003 | E4: The total number of references to selected keywords in Annual Reporting, Sustainability Reports and Websites; in this case related to Equality | F4: Count | G4: Annual Reports, Sustainability Reports and Company Websites
A5: Talk | B5: Count of words in reporting relating to Good Business | C5: talk_gb_count | D5: T004 | E5: The total number of references to selected keywords in Annual Reporting, Sustainability Reports and Websites; in this case related to Good Business | F5: Count | G5: Annual Reports, Sustainability Reports and Company Websites
A6: Talk | B6: Count of words in reporting relating to Climate | C6: talk_climate_count | D6: T005 | E6: The total number of references to selected keywords in Annual Reporting, Sustainability Reports and Websites; in this case related to Climate | F6: Count | G6: Annual Reports, Sustainability Reports and Company Websites
A7: Talk | B7: Count of words in reporting relating to Partnership | C7: talk_partnership_count | D7: T006 | E7: The total number of references to selected keywords in Annual Reporting, Sustainability Reports and Websites; in this case related to Partnership | F7: Count | G7: Annual Reports, Sustainability Reports and Company Websites
A8: Talk | B8: Count of words in reporting relating to Justice | C8: talk_justice_count | D8: T007 | E8: The total number of references to selected keywords in Annual Reporting, Sustainability Reports and Websites; in this case related to Justice | F8: Count | G8: Annual Reports, Sustainability Reports and Company Websites
A9: Talk | B9: Proportion of words in reporting relating to Poverty and Wellbeing | C9: talk_wb_pct | D9: T008 | E9: The total number of references to selected keywords in Annual Reporting, Sustainability Reports and Websites as a proportion of total word count in analysed text; in this case related to Poverty & Wellbeing | F9: Count | G9: Annual Reports, Sustainability Reports and Company Websites
A10: Talk | B10: Proportion of words in reporting relating to Education and Skills | C10: talk_skills_pct | D10: T009 | E10: The total number of references to selected keywords in Annual Reporting, Sustainability Reports and Websites as a proportion of total word count in analysed text; in this case related to Education & Skills | F10: Percentage | G10: Annual Reports, Sustainability Reports and Company Websites
A11: Talk | B11: Proportion of words in reporting relating to Equality | C11: talk_equality_pct | D11: T010 | E11: The total number of references to selected keywords in Annual Reporting, Sustainability Reports and Websites as a proportion of total word count in analysed text; in this case related to Equality | F11: Percentage | G11: Annual Reports, Sustainability Reports and Company Websites
A12: Talk | B12: Proportion of words in reporting relating to Good Business | C12: talk_gb_pct | D12: T011 | E12: The total number of references to selected keywords in Annual Reporting, Sustainability Reports and Websites as a proportion of total word count in analysed text; in this case related to Good Business | F12: Percentage | G12: Annual Reports, Sustainability Reports and Company Websites
... A127: Partnership | B127: Hours dedicated to charity | C127: partnership_hours | D127: P010 | E127: The number of hours a company's employees have spent volunteering for charitable and community organisations. | F127: Hours | G127: Annual Report, Sustainability Report
A128: Partnership | B128: Community, charity and social contributions reach | C128: partnership_contribs_reach | D128: P011
A129: Partnership | B129: Community, charity and social contributions (£) | C129: partnership_contribs | D129: P012 | E129: The total amount or value of charitable donations and volunteering by a company/group. | F129: GBP | G129: Annual Report, Sustainability Report
A130: Justice | B130: Number of fines relating to Planet | C130: justice_fines_planet_count | D130: J001 | E130: The total number of fines, settlements and other financial penalties related to environmental factors issued to the company/group by UK and US regulators since 2016. | F130: Count | G130: The regulatory bodies included are as follows, with the USA bodies having been compiled by Good Jobs First's Violations Tracker (https://www.goodjobsfirst.org/violation-tracker): ICO (UK), FMCSA (USA), USAO (USA), EPA (USA), OFCCP (USA), FRA (USA), OSHA (USA), CFTC (USA), DOJ (USA), ACPD (USA), MSHA (USA), EA (UK), BSEE (USA), OFGEM (UK), OFCOM (UK), Gambling Commission (UK), HSE (UK), OFAC (USA), FED (USA), SFO (UK), FCA (UK), FAA (USA)
A131: Justice | B131: Number of fines relating to People | C131: justice_fines_people_count | D131: J002 | E131: The total value of fines, settlements and other financial penalties related to social factors issued to the company/group by UK and US regulators since 2016. | F131: Count | G131: The regulatory bodies included are as follows, with the USA bodies having been compiled by Good Jobs First's Violations Tracker (https://www.goodjobsfirst.org/violation-tracker): ICO (UK), FMCSA (USA), USAO (USA), EPA (USA), OFCCP (USA), FRA (USA), OSHA (USA), CFTC (USA), DOJ (USA), ACPD (USA), MSHA (USA), EA (UK), BSEE (USA), OFGEM (UK), OFCOM (UK), Gambling Commission (UK), HSE (UK), OFAC (USA), FED (USA), SFO (UK), FCA (UK), FAA (USA)
A132: Justice | B132: Number of human rights accusations not responded to | C132: justice_accusations_response | D132: J003 | E132: The absolute number of human rights accusations, compiled by the Business and Human Rights Resource Centre, that have not been replied to by the company. | F132: Count | G132: BHRRC https://www.business-humanrights.org/
A133: Justice | B133: Response rate to human rights accusations | C133: justice_accusations_rate | D133: J004 | E133: The number of human rights accusations compiled by the Business and Human Rights Resource Centre that a company has responded to as a proportion of the total number of accusations compiled by the Centre. | F133: Percentage | G133: BHRRC https://www.business-humanrights.org/
A134: Justice | B134: BHRRC Modern Slavery Report ranking | C134: justice_slavery | D134: J005 | E134: A ranking by the Business and Human Rights Resource Centres of the FTSE100 companies on their compliance with the Modern Slavery Act. | F134: Rank | G134: BHRRC https://www.business-humanrights.org/
A135: Justice | B135: Value of People fines (£) | C135: justice_fines_people_value | D135: J006 | E135: The total value of fines, settlements and other financial penalties related to social factors issued to the company/group by UK and US regulators since 2016. | F135: GBP | G135: The regulatory bodies included are as follows, with the USA bodies having been compiled by Good Jobs First's Violations Tracker (https://www.goodjobsfirst.org/violation-tracker): ICO (UK), FMCSA (USA), USAO (USA), EPA (USA), OFCCP (USA), FRA (USA), OSHA (USA), CFTC (USA), DOJ (USA), ACPD (USA), MSHA (USA), EA (UK), BSEE (USA), OFGEM (UK), OFCOM (UK), Gambling Commission (UK), HSE (UK), OFAC (USA), FED (USA), SFO (UK), FCA (UK), FAA (USA)
A136: Justice | B136: Value of People fines as a proportion of revenue (%) | C136: justice_fines_people_value_revenue | D136: J007 | E136: The total value of fines, settlements and other financial penalties related to social factors issued to the company/group by UK and US regulators since 2016 as a proportion of total revenue reported by the company/group in the most recently reported year. | F136: Percentage | G136: The regulatory bodies included are as follows, with the USA bodies having been compiled by Good Jobs First's Violations Tracker (https://www.goodjobsfirst.org/violation-tracker): ICO (UK), FMCSA (USA), USAO (USA), EPA (USA), OFCCP (USA), FRA (USA), OSHA (USA), CFTC (USA), DOJ (USA), ACPD (USA), MSHA (USA), EA (UK), BSEE (USA), OFGEM (UK), OFCOM (UK), Gambling Commission (UK), HSE (UK), OFAC (USA), FED (USA), SFO (UK), FCA (UK), FAA (USA)
A137: Justice | B137: Value of Planet fines (£) | C137: justice_fines_planet_value | D137: J008 | E137: The total value of fines, settlements and other financial penalties related to environmental factors issued to the company/group by UK and US regulators since 2016. | F137: GBP | G137: The regulatory bodies included are as follows, with the USA bodies having been compiled by Good Jobs First's Violations Tracker (https://www.goodjobsfirst.org/violation-tracker): ICO (UK), FMCSA (USA), USAO (USA), EPA (USA), OFCCP (USA), FRA (USA), OSHA (USA), CFTC (USA), DOJ (USA), ACPD (USA), MSHA (USA), EA (UK), BSEE (USA), OFGEM (UK), OFCOM (UK), Gambling Commission (UK), HSE (UK), OFAC (USA), FED (USA), SFO (UK), FCA (UK), FAA (USA)
A138: Justice | B138: Value of Planet fines as a proportion of revenue (%) | C138: justice_fines_planet_value_revenue | D138: J009 | E138: The total value of fines, settlements and other financial penalties related to environmental factors issued to the company/group by UK and US regulators since 2016 as a proportion of total revenue reported by the company/group in the most recently reported year. | F138: Percentage | G138: The regulatory bodies included are as follows, with the USA bodies having been compiled by Good Jobs First's Violations Tracker (https://www.goodjobsfirst.org/violation-tracker): ICO (UK), FMCSA (USA), USAO (USA), EPA (USA), OFCCP (USA), FRA (USA), OSHA (USA), CFTC (USA), DOJ (USA), ACPD (USA), MSHA (USA), EA (UK), BSEE (USA), OFGEM (UK), OFCOM (UK), Gambling Commission (UK), HSE (UK), OFAC (USA), FED (USA), SFO (UK), FCA (UK), FAA (USA)
A139: Justice | B139: Number of upheld employment tribunal cases | C139: justice_et_upheld | D139: J010 | E139: The total number of UK Employment Tribunal cases since 2017 involving the company which saw the Tribunal uphold at least one of the claims of the employee/former employee. | F139: Count | G139: UK Employment Tribunal
A140: Justice | B140: Number of upheld employment tribunal cases per employee | C140: justice_et_upheld_employees | D140: J011 | E140: The total number of UK Employment Tribunal cases since 2017 involving the company which saw the Tribunal uphold at least one of the claims of the employee/former employee as a proportion of total number of employees. | F140: Percentage | G140: UK Employment Tribunal
... A144: Misc | B144: Number of employees in previous year | C144: misc_employees_previous | D144: M002 | E144: The total number of people employed by a company/group in the previously reported year. If reported, we have used FTE or average number of employees. | F144: Count | G144: Annual Report
A145: Misc | B145: Market capitalisation | C145: misc_cap | D145: M003 | G145: London Stock Exchange

Sheet codebook_full
A1: Indicator Name | B1: Pillar | C1: Code | D1: Logical Order | E1: Programmatic Name | F1: On website? | G1: Send to FTSE? | H1: Used for C100 | I1: Methodology | J1: Scaled | K1: Search terms | L1: Description | M1: Unit | N1: Data Type | O1: Source | P1: Data location | Q1: What needs to happen in the code | R1: Exclude Tickers | S1: Imputation | T1: Normalisation | U1: Transform | V1: Negative Weight | W1: Reward/Penalty
A2: Scope 3 Score | B2: Climate | C2: C023 | D2: 1 | E2: climate_scope3_score | I2: Score based on Scope 3 emissions reporting: - If Scope 3 emissions are not reported, score = 0 - If Scope 3 emissions are reported and < Scope 1&2, score = 1 - If Scope 3 emissions are reported and > Scope 1&2, score = 2 | J2: None | L2: This indicator captures whether a company's Scope 3 reporting is accurate. This is based upon research findings that Scope 3 emissions are typically higher than Scope 1 and 2. Our methodology is as follows: - If Scope 3 emissions are not reported, score = 0 - If Scope 3 emissions are reported and < Scope 1&2, score = 1 - If Scope 3 emissions are reported and > Scope 1&2, score = 2 | M2: 0/1/2 | N2: Numeric | O2: Bespoke | P2: Programmatic | Q2: Score the Scope 3 emissions 0, 1 or 2
A3: Total Scope 3 Greenhouse Gas Emissions | B3: Climate | C3: C019 | D3: 2 | E3: climate_scope3 | F3: 1 | G3: 1 | H3: 1 | I3: PLEASE FLAG WHAT'S INCLUDED (ie. employee travel). Please find total Scope 3 emissions reported in annual reports. | J3: None | K3: scope 3, emissions | L3: The amount of Scope 3 emissions (emissions along a company's value chain that they are indirectly responsible for) in tonnes. | M3: Tonnes of CO2e | N3: Numeric | O3: Annual Report, Sustainability Report | P3: Annual Report | S3: Max | T3: Reverse Normalise | U3: Square Root Transform | V3: 1 | W3: -1
A4: Total Scope 1 & Scope 2 Greenhouse Gas Emissions | B4: Climate | C4: C001 | D4: 3 | E4: climate_scope12 | F4: 1 | G4: 1 | H4: 1 | I4: The sum of Scope 1 and Scope 2 emissions. If they give one figure and don't specify whether it's Market Based or Location Based, take the figure available. If they give two figures, choose market-based. If they just provide location-based, use that. | J4: By revenue | K4: scope, scope 1, scope 2, emissions | L4: The amount of Scope 1 (all direct emissions that are controlled or owned by an organisation) and Scope 2 (indirect emissions associated with the purchase of electricity, steam, heat, or cooling) emissions reported by a company in its most recent annual report, as measured in tonnes of carbon dioxide equivalent (CO2e). Market-based Scope 2 emissions are taken where available as they represent the emissions a company is responsible for through its purchasing decisions, as opposed to 'location-based' which represents the average emissions intensity of grids on which energy consumption occurs. | M4: Tonnes of CO2e | N4: Numeric | O4: Annual Report, Sustainability Report | P4: Annual Report | S4: Max | T4: Reverse Normalise | U4: Square Root Transform | V4: 1 | W4: -1
A5: Total Water Consumption | B5: Climate | C5: C004 | D5: 4 | E5: climate_water | F5: 1 | G5: 1 | H5: 1 | I5: Find Total Water Consumption in the annual report. The number should be readily available, however, if it is not, please add any figure reported as either water 'consumption', 'use' or 'extraction' and mark clearly in the FLAG column. Be careful to check the units. | J5: By revenue | K5: water, consumption | L5: Total Water Consumption includes both direct (operational) and indirect (supply-chain) water footprints. | M5: Cubic Metres | N5: Numeric | O5: Annual Report, Sustainability Report | P5: Annual Report | S5: Max | T5: Reverse Normalise | U5: Square Root Transform | V5: 1 | W5: -1
A6: Total Energy Consumption | B6: Climate | C6: C007 | D6: 5 | E6: climate_energy | F6: 1 | G6: 1 | H6: 1 | I6: Find value and convert to MWh (ie. using Google) | J6: By revenue | K6: energy | L6: The total energy consumed by a company per year. | M6: MWH | N6: Numeric | O6: Annual Report, Sustainability Report | P6: Annual Report | S6: Max | T6: Reverse Normalise | U6: Square Root Transform | V6: 1 | W6: -1
A7: % Energy Usage from Renewable Sources | B7: Climate | C7: C005 | D7: 6 | E7: climate_renewable_energy | F7: 1 | G7: 1 | H7: 1 | I7: The figure is calculated as the percentage of total energy usage that is accounted for by energy from renewable sources. Please note that it is energy, not electricity. | J7: None | K7: renewable energy, renewable, renewables | L7: The percentage of total energy used by a company/group that is from a renewable source (e.g. wind, solar, etc). | M7: Percentage | N7: Numeric | O7: Annual Report, Sustainability Report | P7: Annual Report | S7: 0 | V7: 1 | W7: 1
A8: % Electricity Usage from Renewable Sources | B8: Climate | C8: C006 | D8: 7 | E8: climate_renewable_electricity | F8: 1 | G8: 1 | H8: 1 | I8: The figure is calculated as the percentage of total electricity usage that is accounted for by energy from renewable sources. Please note that it is electricity not energy. | J8: None | K8: electricity, renewable sources | L8: The percentage of total electricity used by a company/group that is from a renewable source (e.g. wind, solar, etc). | M8: Percentage | N8: Numeric | O8: Annual Report, Sustainability Report | P8: Annual Report | S8: 0 | V8: 1 | W8: 1
A9: Total Waste Produced | B9: Climate | C9: C018 | D9: 8 | E9: climate_waste | F9: 1 | G9: 1 | H9: 1 | I9: The total amount of waste produced by a company. Please note the units and convert into tonnes. | J9: By revenue | K9: waste | L9: The total amount of waste produced by a company. | M9: Tonnes | N9: Numeric | O9: Annual Report, Sustainability Report | P9: Annual Report | S9: Max | T9: Reverse Normalise | U9: Square Root Transform | V9: 1 | W9: -1
A10: % Waste Recycled or Re-used | B10: Climate | C10: C010 | D10: 9 | E10: climate_waste_recycled | F10: 1 | G10: 1 | H10: 1 | I10: The absolute percentage of total waste produced by a company/group that is reported as re-used or recycled. This can be found in the annual report. | J10: None | K10: recycled, reuse, waste | L10: The absolute percentage of total waste produced by a company/group that is reported as re-used or recycled. | M10: Percentage | N10: Numeric | O10: Annual Report, Sustainability Report | P10: Annual Report | S10: 0 | V10: 1 | W10: 1
A11: % Waste to Landfill | B11: Climate | C11: C009 | D11: 10 | E11: climate_waste_landfill | F11: 1 | G11: 1 | H11: 1 | I11: PLEASE NOTE: DON'T INFER FROM WASTE RECYCLED - THEY ARE NOT THE SAME FIGURE. Find the absolute percentage of total waste produced by a company/group that is sent to landfill in annual reports. You may need to add up a variety of numbers. Please write all numbers in the Flag column. | J11: None | K11: landfill, waste | L11: The absolute percentage of total waste produced by a company/group that is sent to landfill. | M11: Percentage | N11: Numeric | O11: Annual Report, Sustainability Report | P11: Annual Report | S11: Max | V11: -1 | W11: -1
A12: CDP Water Security Rating | B12: Climate | C12: C014 | D12: 11 | E12: climate_cdp_water | F12: 1 | G12: 1 | H12: 1 | I12: Go to the CDP website (https://www.cdp.net/en/search) and search for the company name. Go to their Water Security response and find the letter that corresponds to their water security rating (e.g. A - D-). | J12: None | K12: CDP, CDP Water | L12: The Carbon Disclosure Project (CDP) runs the global disclosure system for companies to manage their environmental impacts, and invites reporting on current practices and procedures, risks and opportunities, and strategy. The CDP Water Security Rating involves reporting on current practices and procedures, risks and opportunities, and targets/strategy. It is scored A to D- based on a company's questionnaire submission. | M12: Grade of A to F | N12: Categorical | O12: CDP https://www.cdp.net/en/companies/companies-scores | P12: Programmatic | Q12: Figure out if we can scrape. If not, change to Additional Indicators | V12: 1 | W12: 1
A13: CDP Forests Rating | B13: Climate | C13: C013 | D13: 12 | E13: climate_cdp_forestry | F13: 1 | G13: 1 | H13: 1 | I13: Go to the CDP website (https://www.cdp.net/en/search) and search for the company name. Go to their Forests response and find the letter that corresponds to their forestry rating (e.g. A - D-). | J13: None | K13: CDP, CDP Forests | L13: The Carbon Disclosure Project (CDP) runs the global disclosure system for companies to manage their environmental impacts, and invites reporting on current practices and procedures, risks and opportunities, and strategy. The CDP Timber and Forestry Rating records data on commodity consumption, origin and certifications. It is scored A to D- based on a company's questionnaire submission. | M13: Grade of A to F | N13: Categorical | O13: CDP https://www.cdp.net/en/companies/companies-scores | P13: Programmatic | Q13: Scrape | V13: 1 | W13: 1
A14: CDP Climate Rating | B14: Climate | C14: C012 | D14: 13 | E14: climate_cdp_climate | F14: 1 | G14: 1 | H14: 1 | I14: Go to the CDP website (https://www.cdp.net/en/search) and search for the company name. Go to their Climate Change response and find the letter that corresponds to their climate rating (e.g. A - D-). | J14: None | K14: CDP, CDP Climate | L14: The Carbon Disclosure Project (CDP) runs the global disclosure system for companies to manage their environmental impacts, and invites reporting on current practices and procedures, risks and opportunities, and strategy. The CDP Climate Rating records data on emissions, climate risk and opportunities, etc, and is scored A to D- based on a company's questionnaire submission. | M14: Grade of A to F | N14: Categorical | O14: CDP https://www.cdp.net/en/companies/companies-scores | P14: Programmatic | Q14: Scrape | V14: 1 | W14: 1
A15: % Ethnic Minority Pay Gap in UK | B15: Equality | C15: E013 | D15: 14 | E15: equality_bame_pay | F15: 1 | G15: 1 | H15: 0 | I15: UK Data ONLY (PLEASE ADD GLOBAL FIGURE TO FLAG COLUMN). The percentage (%) pay gap for people who are BAME (Black Asian and Minority Ethnic Group). | J15: None | K15: ethnic minority, BAME | L15: The absolute percentage difference in pay between Black, Asian or Minority Ethnic (BAME) and non-BAME identifying employees at the company/group. | M15: Percentage | N15: Numeric | O15: Annual Report | P15: Annual Report | Q15: Score data on pay gaps as a binary in the code | S15: 100 | T15: Reverse Normalise | U15: Absolute Transform | V15: 1 | W15: -1
A16: % Median Gender Pay Gap in UK | B16: Equality | C16: E006 | D16: 15 | E16: equality_gender_pay | F16: 1 | G16: 1 | H16: 0 | J16: None | K16: gender pay gap, median gender pay | L16: The absolute percentage difference between the median pay of a company's male and female employees across the company, as reported to the UK government. | M16: Percentage | N16: Numeric | O16: GOV.uk | P16: Programmatic | Q16: Figure out if we can scrape (look at description and methodology for guidance on how subsidiaries work). If not, change to Annual Report, and add 1 in AR column | S16: Max | T16: Reverse Normalise | U16: Absolute Transform | V16: 1
A17: % Median Gender Bonus Gap in UK | B17: Equality | C17: E024 | D17: 16 | E17: equality_gender_bonus | F17: 1 | G17: 1 | H17: 0 | J17: None | L17: The median percentage difference in bonuses between a company's male and female employees in the UK. A positive gender bonus gap indicates that men are paid more than women. A negative bonus pay gap indicates that women are paid more than men. This information can be found in their UK Government Gender Pay Gap reports (https://gender-pay-gap.service.gov.uk/), Annual Reports, Sustainability reports, or on their website. This indicator is for UK employees only. A negative gender bonus gap is scored equally to no pay gap. | M17: Percentage | N17: Numeric | O17: GOV.uk | P17: Programmatic | Q17: Figure out if we can scrape (look at description and methodology for guidance on how subsidiaries work). If not, change to Annual Report, and add 1 in AR column | S17: Max | T17: Reverse Normalise | U17: Absolute Transform | V17: 1
A18: % Senior Management who are Female | B18: Equality | C18: E002 | D18: 17 | E18: equality_female_management | F18: 1 | G18: 1 | H18: 0 | I18: PLEASE NOTE - SENIOR MANAGEMENT DOES NOT INCLUDE BOARD OF DIRECTORS. Only collect if company provides this number (they should, and it would be in their annual report/gender pay report). If they do not use the term "senior management" exactly, add note about what kind of (senior) manager we've got. It might be called directors/leaders. | J18: None | K18: senior management | L18: The percentage of senior management at the company/group that are female. | M18: Percentage | N18: Numeric | O18: Annual Report, Pay Gap Report | P18: Annual Report | S18: 0 | V18: 1 | W18: 1
A19: % Employees who are Female | B19: Equality | C19: E003 | D19: 18 | E19: equality_female_employees | F19: 1 | G19: 1 | H19: 0 | I19: The percentage (%) of the total workforce at the company who are female. Please note that this should be FTE if available. It will usually be reported in annual report or gender pay reports. | J19: None | K19: women, female, employees | L19: The percentage of total employees at the company/group that are female. | M19: Percentage | N19: Numeric | O19: Annual Report, Pay Gap Report | P19: Annual Report | S19: 0 | V19: 1 | W19: 1
A20: % UK Senior Management from an Ethnic Minority Background | B20: Equality | C20: E014 | D20: 19 | E20: equality_bame_management | F20: 1 | G20: 1 | H20: 0 | I20: UK Data ONLY (PLEASE ADD GLOBAL FIGURE TO FLAG COLUMN). PLEASE NOTE - SENIOR MANAGEMENT DOES NOT INCLUDE BOARD OF DIRECTORS Senior management is not board of directors; only collect if company provides; if not "senior management" exactly, add note about what kind of (senior) manager we've got. | J20: None | K20: ethnic minority, BAME | L20: The percentage of senior management at the company who identify as Black, Asian or Minority Ethnic (BAME). | M20: Percentage | N20: Numeric | O20: Annual Report | P20: Annual Report | S20: 0 | V20: 1 | W20: 1
A21: % UK Employees from an Ethnic Minority Background | B21: Equality | C21: E012 | D21: 20 | E21: equality_bame_employees | F21: 1 | G21: 1 | H21: 0 | I21: UK Data ONLY (PLEASE ADD GLOBAL FIGURE TO FLAG COLUMN). The percentage (%) of the total workforce at the company who are BAME (Black Asian and Minority Ethnic Group). | J21: None | K21: ethnic minority, BAME | L21: The percentage of total employees at the company/group who identify as Black, Asian or Minority Ethnic (BAME). | M21: Percentage | N21: Numeric | O21: Annual Report | P21: Annual Report | S21: 0 | V21: 1 | W21: 1
A22: % UK Employees who are LGBTQ+ | B22: Equality | C22: E015 | D22: 21 | E22: equality_lgbt_employees | F22: 1 | G22: 1 | H22: 0 | I22: Find value in annual report. It may also be in a diversity / gender report too. If missing, write 'MISSING'. | J22: None | K22: LGBTQIA+, LGBT, LGBTQ, sexual orientation | L22: The percentage of total employees at the company/group who identify as Lesbian, Gay, Bisexual, Transgender, Queer or other non-binary groups (LGBTQ+). | M22: Percentage | N22: Numeric | O22: Annual Report | P22: Annual Report | S22: 0 | V22: 1 | W22: 1
A23: % UK Senior Management who are LGBTQ+ | B23: Equality | C23: E017 | D23: 22 | E23: equality_lgbt_management | F23: 1 | G23: 1 | H23: 0 | I23: UK Data ONLY (PLEASE ADD GLOBAL FIGURE TO FLAG COLUMN). PLEASE NOTE - SENIOR MANAGEMENT DOES NOT INCLUDE BOARD OF DIRECTORS Senior management is not board of directors; only collect if company provides; if not "senior management" exactly, add note about what kind of (senior) manager we've got. | J23: None | K23: LGBTQIA+, LGBT, LGBTQ, sexual orientation | L23: The percentage of senior management at the company/group who identify as LGBTQ+. | M23: Percentage | N23: Numeric | O23: Annual Report | P23: Annual Report | S23: 0 | V23: 1 | W23: 1
A24: % UK Employees who are Disclosed as Disabled | B24: Equality | C24: E018 | D24: 23 | E24: equality_disability_employees | F24: 1 | G24: 1 | H24: 0 | I24: Find value in annual report. It may also be in a diversity report too. If missing, write 'MISSING'. | J24: None | K24: disabled, disability, disabilities | L24: The percentage of total employees at the company/group with disclosed disabilities. | M24: Percentage | N24: Numeric | O24: Annual Report | P24: Annual Report | S24: 0 | V24: 1 | W24: 1
A25: % UK Senior Management who are Disclosed as Disabled | B25: Equality | C25: E020 | D25: 24 | E25: equality_disability_management | F25: 1 | G25: 1 | H25: 0 | I25: UK Data ONLY (PLEASE ADD GLOBAL FIGURE TO FLAG COLUMN). PLEASE NOTE - SENIOR MANAGEMENT DOES NOT INCLUDE BOARD OF DIRECTORS Senior management is not board of directors; only collect if company provides; if not "senior management" exactly, add note about what kind of (senior) manager we've got. | J25: None | K25: disabled, disability, disabilities | L25: The percentage of senior management at the company/group who are disclosed as disabled. | M25: Percentage | N25: Numeric | O25: Annual Report | P25: Annual Report | S25: 0 | V25: 1 | W25: 1
A26: % Directors who are Female | B26: Equality | C26: E008 | D26: 25 | E26: equality_gender_directors | F26: 1 | G26: 1 | H26: 0 | I26: The proportion of a company’s board of directors that is female, not including secretaries. As there has been a historic trend of male dominated boards and the relative few numbers of people on a board we have made the decision that the larger proportion the better. This indicator includes non-executive directors. This information should be in the annual report and on the website. | J26: None | K26: directors, board of directors | L26: The proportion of a company’s board of directors that is female (excluding secretaries). As there has been a historic trend of male-dominated boards, we have made the decision that the larger proportion of females on the board, the better. | M26: Percentage | N26: Numeric | O26: Annual Report, Gender Pay Gap Report | P26: Programmatic | Q26: Scrape | S26: 0 | V26: 1 | W26: 1
A27: % New Directors (appointed in past three years) who are Female | B27: Equality | C27: E009 | D27: 26 | E27: equality_gender_appointments | F27: 1 | G27: 1 | H27: 0 | I27: Any new Directors are counted if they were appointed in the period up to three years before the Data of the most recent update of the Responsibility 100 Index, where the Data of appointment is taken to be the Data that their appointment was announced on Companies House. | J27: None | K27: directors, board of directors, female | L27: The proportion of recent hires (over the past three years) of directors to a company’s board who are female. Given that very few of the FTSE 100 boards were evenly proportioned, and that the highest hiring proportion is 75% we have decided that higher a hiring proportion of females is better. | M27: Percentage | N27: Numeric | O27: Annual Report | P27: Programmatic | Q27: Scrape | S27: 0 | V27: 1 | W27: 1
A28: Length of Primary Parental Leave | B28: Equality | C28: E004 | D28: 27 | E28: equality_leave_primary | F28: 1 | G28: 1 | H28: 0 | I28: The total amount of paid primary parental leave (sometimes known as maternity leave). The figure we collect represents the amount of paid leave, supplementary to statutory parental leave. I.e. if a company offers 26 weeks fully paid leave, plus 18 weeks statutory pay, we collect the 26 week figure. If a company offers 8 weeks at 90% pay, we collect 8x0.9 = 7.2 weeks. | J28: None | K28: parental leave | L28: The total length of fully paid maternity leave provided by the company/group, according to their maternity/paternity policy where one exists. | M28: Weeks | N28: Numeric | O28: Maternity/Paternity Policy, Annual Report | P28: Annual Report | S28: 0 | V28: 1 | W28: 1
A29: Length of Secondary Parental Leave | B29: Equality | C29: E005 | D29: 28 | E29: equality_leave_secondary | F29: 1 | G29: 1 | H29: 0 | I29: The total amount of paid secondary parental leave (sometimes known as paternity leave). The figure we collect represents the amount of paid leave, supplementary to statutory parental leave. | J29: None | K29: parental leader | L29: The total length of fully paid parental leave provided by the company/group to 'secondary' parental figures', according to their maternity/paternity policy where one exists. | M29: Weeks | N29: Numeric | O29: Maternity/Paternity Policy, Annual Report | P29: Annual Report | S29: 0 | V29: 1 | W29: 1
A30: Level of WISE Membership | B30: Membership | C30: E011 | D30: 29 | E30: equality_wise_level | F30: 1 | G30: 1 | H30: 0 | I30: This indicator discloses the level of a company's membership in the WISE campaign (Women in Science and Engineering). 1 indicates the company is an Online Member; 2 indicates Core Member; 3 indicates Premium Member; 4 indicates Strategic Partner. This can be found in annual reports or on the company's website. | J30: None | K30: WISE membership, women in stem | L30: This indicator discloses the level of a company's membership in the WISE campaign (Women in Science and Engineering). 1 indicates the company is an Online Member; 2 indicates Core Member; 3 indicates Premium Member; 4 indicates Strategic Partner. | M30: 4/3/2/1/0 | N30: Categorical | O30: WISE Campaign https://www.wisecampaign.org.uk/ | P30: Programmatic | Q30: Scrape | S30: 0 | V30: 1 | W30: 1
A31: % Annual Graduate / Apprentice Intake who are Female | B31: Equality | C31: E001 | D31: 30 | E31: equality_female_graduates | F31: 1 | G31: 1 | H31: 0 | I31: The percentage (%) of newly hired graduates at the company who are female. This can be found in annual report or in gender pay reports. | J31: None | K31: graduates, grads, apprentices, early careers, young people, early career opportunities | L31: The percentage of recent graduates hired by the company/group that are female. | M31: Percentage | N31: Numeric | O31: Annual Report, Pay Gap Report | P31: Annual Report | S31: 0 | V31: 1 | W31: 1
A32: Revenue | B32: Good Business | C32: G010 | D32: 31 | E32: gb_revenue | G32: 1 | H32: 0 | I32: This number can be found in the annual report, in the financial section. If it is not in GBP, take the average currecy conversion over the reporting period, or Jan-Jan if no reporting period using this tool https://docs.google.com/spreadsheets/d/1pFxv18Kp2d0EmS6BA4wrlqL_gsbwE8W0h-FLYPWFFog/edit#gid=0 | J32: None | K32: revenue | L32: The revenue of the company. | M32: GBP | N32: Numeric | O32: Yahoo Finance | P32: Annual Report | S32: 0 | V32: 1 | W32: 1
A33: Revenue 1 Year Prior | B33: Good Business | C33: G033 | D33: 32 | E33: collection_revenue_1_prior | I33: Revenue, turnover, net sales - these are all valid. They can be found in an annual report (found on companies House or on their website). If it is not in GBP, take the average currecy conversion over the reporting period, or Jan-Jan if no reporting period using this tool https://docs.google.com/spreadsheets/d/1pFxv18Kp2d0EmS6BA4wrlqL_gsbwE8W0h-FLYPWFFog/edit#gid=0 | J33: None | K33: revenue | L33: Dummy indicator to calculate revenue growth | M33: GBP | O33: Annual Report | P33: Annual Report | Q33: Pull in data from correct year
A34: Revenue 2 Years Prior | B34: Good Business | C34: G034 | D34: 33 | E34: collection_revenue_2_prior | I34: Revenue, turnover, net sales - these are all valid. They can be found in an annual report (found on companies House or on their website). For currency conversions, use this website: https://www.ofx.com/en-gb/forex-news/historical-exchange-rates/ and take the average from the last 3 years (31 Dec 2020 -- 31 Dec 2022) 0.867502 EUR: 1 GBP 0.772778 USD: 1 GBP 0.82542 CHF: 1 GBP | J34: None | K34: revenue | L34: Dummy indicator to calculate revenue growth | M34: GBP | O34: Annual Report | P34: Annual Report | Q34: Pull in data from correct year
A35: Revenue 3 Years Prior | B35: Good Business | C35: G035 | D35: 34 | E35: collection_revenue_3_prior | I35: Revenue, turnover, net sales - these are all valid. They can be found in an annual report (found on companies House or on their website). If it is not in GBP, take the average currecy conversion over the reporting period, or Jan-Jan if no reporting period using this tool https://docs.google.com/spreadsheets/d/1pFxv18Kp2d0EmS6BA4wrlqL_gsbwE8W0h-FLYPWFFog/edit#gid=0 | J35: None | K35: revenue | L35: Dummy indicator to calculate revenue growth | M35: GBP | O35: Annual Report | P35: Annual Report | Q35: Pull in data from correct year
A36: Operating Profit | B36: Good Business | C36: G036 | D36: 35 | E36: collection_profit | I36: In annual report, look for profit. Prefer operating profit. If operating profit is not present, take profit (loss) before taxation. If it is not in GBP, take the average currecy conversion over the reporting period, or Jan-Jan if no reporting period using this tool https://docs.google.com/spreadsheets/d/1pFxv18Kp2d0EmS6BA4wrlqL_gsbwE8W0h-FLYPWFFog/edit#gid=0 | J36: None | K36: profit | L36: Dummy indicator to calculate operating profit margin | M36: GBP | O36: Annual Report | P36: Annual Report | Q36: Create indicator
A37: % Operating Profit Margin | B37: Good Business | C37: G037 | D37: 36 | E37: gb_profit_revenue | I37: Programmatic - operating profit / revenue | J37: None | K37: profit margin | L37: Operating profit is the total income a company generates from sales after paying off all operating expenses, such as rent, employee payroll, equipment and inventory costs. The operating profit figure excludes gains or losses from interest, taxes and investments. Operating Profit Margin = Operating Profit / Total Revenue | M37: Percentage | O37: Annual Report | P37: Programmatic | Q37: Check that this is profit / revenue - can just do by scaling by revenue?
A38: % Average Revenue Growth Over 3 Years | B38: Good Business | C38: G011 | D38: 37 | E38: gb_revenue_growth | F38: 1 | G38: 0 | H38: 0 | I38: This number can be found in the annual report, in the financial section. Write the number for last year in the flag column and do the calculation. | J38: None | K38: revenue, revenue growth | L38: The total amount of revenue growth, as a percentage, at a company/group in the most recently reported year. | M38: Percentage (Change) | N38: Numeric | O38: Yahoo Finance | P38: Programmatic | Q38: Create indicator | T38: Normalise Around Zero | V38: 1 | W38: 1
A39: Total Tax Payable | B39: Good Business | C39: G014 | D39: 38 | E39: gb_tax | G39: 1 | H39: 0 | I39: This number can be found in the annual report, in the financial section. If it is not in GBP, take the average currecy conversion over the reporting period, or Jan-Jan if no reporting period using this tool https://docs.google.com/spreadsheets/d/1pFxv18Kp2d0EmS6BA4wrlqL_gsbwE8W0h-FLYPWFFog/edit#gid=0 | J39: None | K39: tax | L39: The total tax expense in £ of a company/group in the most recently reported year. This will most likely be disclosed alongside CEO pay in 'Remuneration' section of Annual Report. Use this converter to do a currency conversion over the dates of the AR (ideally using moneths, but do Jan-Jan if none available) https://docs.google.com/spreadsheets/d/1pFxv18Kp2d0EmS6BA4wrlqL_gsbwE8W0h-FLYPWFFog/edit#gid=0 | M39: GBP | N39: Numeric | O39: Yahoo Finance | P39: Programmatic | S39: 0 | V39: 1 | W39: 1
A40: % Effective Tax Rate | B40: Good Business | C40: G001 | D40: 39 | E40: gb_tax_effective | F40: 1 | G40: 1 | H40: 0 | I40: This is the effective tax rate for the company or group as reported for a given year. Only include this value if it is specifically defined as the 'effective tax rate'. It is often in a range between 15-27%. If it is blank, write MISSING. | J40: None | K40: effective tax rate, tax rate, adjusted tax | L40: The amount of tax a company has paid as a proportion of its income as reported within its latest consolidated income statement. | M40: Percentage | N40: Numeric | O40: Annual Report | P40: Annual Report | S40: 19(tax) | V40: 1 | W40: 1
...

Sheet company_info
A1: ticker | B1: company_name | C1: yahoo_name | D1: website_ticker | E1: yahoo_ticker | F1: sector | G1: industry | H1: company_description | I1: companies_house_id | J1: companies_house_link | K1: search_terms | L1: violation_tracker_name | M1: glassdoor_url
A2: AAF | B2: Airtel Africa | C2: {=xlookup(B2, sectors!A:A, sectors!A:A)} -> Airtel Africa | D2: =left(E2, 3) -> AAF | E2: AAF.L | F2: {=xlookup(A2, sectors!B:B, sectors!C:C)} -> Retail & Services | G2: {=XLOOKUP(A2, sectors!B:B, sectors!E:E)} -> Telecommunications | H2: Airtel Africa is a multinational company that provides telecommunications and mobile money services in 14 countries in Africa, primarily in East, Central and West Africa. Airtel Africa is majority owned by the Indian telecommunications company Bharti Airtel. | I2: 11462215 | J2: ="https://find-and-update.company-information.service.gov.uk/company/"&$I2 -> https://find-and-update.company-information.service.gov.uk/company/11462215 | K2: airtel | M2: https://www.glassdoor.co.uk/Overview/Working-at-Bharti-Airtel-EI_IE38320.11,24.htm
A3: AAL | B3: Anglo American | C3: Anglo American plc | D3: =left(E3, 3) -> AAL | E3: AAL.L | F3: {=xlookup(A3, sectors!B:B, sectors!C:C)} -> Mining & Extraction | G3: {=XLOOKUP(A3, sectors!B:B, sectors!E:E)} -> Mining | H3: Anglo American is a multinational mining company that is the world's largest producer of platinum, with around 40% of world output, as well as being a major producer of diamonds, copper, nickel, iron ore, polyhalite and steelmaking coal. | I3: 03564138 | J3: ="https://find-and-update.company-information.service.gov.uk/company/"&$I3 -> https://find-and-update.company-information.service.gov.uk/company/03564138 | K3: anglo american | L3: Anglo American PLC | M3: https://www.glassdoor.co.uk/Overview/Working-at-Anglo-American-EI_IE3491.11,25.htm
A4: ABDN | B4: Abrdn | C4: {=xlookup(B4, sectors!A:A, sectors!A:A)} -> Abrdn | D4: =left(E4, 3) -> ABD | E4: ABDN.L | F4: {=xlookup(A4, sectors!B:B, sectors!C:C)} -> Financial Services | G4: {=XLOOKUP(A4, sectors!B:B, sectors!E:E)} -> Financial Services | H4: Abrdn is an investment management group, managing assets for both institutions and private investors from offices around the world. | I4: SC286832 | J4: ="https://find-and-update.company-information.service.gov.uk/company/"&$I4 -> https://find-and-update.company-information.service.gov.uk/company/SC286832 | K4: abrdn | L4: Abrdn PLC | M4: https://www.glassdoor.co.uk/Overview/Working-at-abrdn-EI_IE10239.11,16.htm
A5: ABF | B5: Associated British Foods | C5: {=xlookup(B5, sectors!A:A, sectors!A:A)} -> Associated British Foods | D5: =left(E5, 3) -> ABF | E5: ABF.L | F5: {=xlookup(A5, sectors!B:B, sectors!C:C)} -> Food & Beverage | G5: {=XLOOKUP(A5, sectors!B:B, sectors!E:E)} -> Food Producers | H5: Associated British Foods plc is a multinational food processing and retailing company. Its ingredients division is the world's second-largest producer of both sugar and baker's yeast and a major producer of other ingredients including emulsifiers, enzymes and lactose. | I5: 00293262 | J5: ="https://find-and-update.company-information.service.gov.uk/company/"&$I5 -> https://find-and-update.company-information.service.gov.uk/company/00293262 | K5: associated british foods, primark, allied bakeries | L5: Associated British Foods | M5: https://www.glassdoor.co.uk/Overview/Working-at-Associated-British-Foods-EI_IE10110.11,35.htm
A6: ADM | B6: Admiral Group | C6: {=xlookup(B6, sectors!A:A, sectors!A:A)} -> Admiral Group | D6: =left(E6, 3) -> ADM | E6: ADM.L | F6: {=xlookup(A6, sectors!B:B, sectors!C:C)} -> Financial Services | G6: {=XLOOKUP(A6, sectors!B:B, sectors!E:E)} -> Non-life Insurance | H6: Admiral Group plc is a global financial services company offering insurance products, including motor, household, travel and pet insurance, and personal lending products. | I6: 03849958 | J6: ="https://find-and-update.company-information.service.gov.uk/company/"&$I6 -> https://find-and-update.company-information.service.gov.uk/company/03849958 | K6: admiral | L6: Admiral Group | M6: https://www.glassdoor.co.uk/Overview/Working-at-Admiral-Group-EI_IE35772.11,24.htm
A7: AHT | B7: Ashtead Group | C7: {=xlookup(B7, sectors!A:A, sectors!A:A)} -> Ashtead Group | D7: =left(E7, 3) -> AHT | E7: AHT.L | F7: {=xlookup(A7, sectors!B:B, sectors!C:C)} -> Retail & Services | G7: {=XLOOKUP(A7, sectors!B:B, sectors!E:E)} -> Support Services | H7: Ashtead Group is an international equipment rental company with national networks in the US, UK and Canada, trading under the name Sunbelt Rentals. | I7: 01807982 | J7: ="https://find-and-update.company-information.service.gov.uk/company/"&$I7 -> https://find-and-update.company-information.service.gov.uk/company/01807982 | K7: ashtead | L7: Ashtead Group PLC | M7: https://www.glassdoor.co.uk/Reviews/Sunbelt-Rentals-Reviews-E19665.htm
A8: ANTO | B8: Antofagasta | C8: Antofagasta plc | D8: ANTO | E8: ANTO.L | F8: {=xlookup(A8, sectors!B:B, sectors!C:C)} -> Mining & Extraction | G8: {=XLOOKUP(A8, sectors!B:B, sectors!E:E)} -> Mining | H8: Antofagasta Plc is a Chilean multinational company, which engages in copper mining, transport, and water distribution businesses. | I8: 01627889 | J8: ="https://find-and-update.company-information.service.gov.uk/company/"&$I8 -> https://find-and-update.company-information.service.gov.uk/company/01627889 | K8: antofagasta | M8: https://www.glassdoor.co.uk/Overview/Working-at-Antofagasta-EI_IE11472.11,22.htm
A9: AUTO | B9: Auto Trader Group | C9: {=xlookup(B9, sectors!A:A, sectors!A:A)} -> Auto Trader Group | D9: AUTO | E9: AUTO.L | F9: {=xlookup(A9, sectors!B:B, sectors!C:C)} -> Retail & Services | G9: {=XLOOKUP(A9, sectors!B:B, sectors!E:E)} -> Media | H9: Auto Trader Group is a British automotive online marketplace and classified advertising business. It enables the buying and selling of new and used vehicles by private sellers and trade retailers. | I9: 09439967 | J9: ="https://find-and-update.company-information.service.gov.uk/company/"&$I9 -> https://find-and-update.company-information.service.gov.uk/company/09439967 | K9: auto trader | M9: https://www.glassdoor.co.uk/Overview/Working-at-Auto-Trader-UK-EI_IE505215.11,25.htm
A10: AV. | B10: Aviva | C10: {=xlookup(B10, sectors!A:A, sectors!A:A)} -> Aviva | D10: =left(E10, 3) -> AV. | E10: AV.L | F10: {=xlookup(A10, sectors!B:B, sectors!C:C)} -> Financial Services | G10: {=XLOOKUP(A10, sectors!B:B, sectors!E:E)} -> Life Insurance | H10: Aviva is a British multinational insurance company with 18 million customers across its core markets of the United Kingdom, Ireland and Canada. In the United Kingdom, Aviva is the largest general insurer and a leading life and pensions provider. | I10: 02468686 | J10: ="https://find-and-update.company-information.service.gov.uk/company/"&$I10 -> https://find-and-update.company-information.service.gov.uk/company/02468686 | K10: aviva | M10: https://www.glassdoor.co.uk/Overview/Working-at-Aviva-EI_IE311641.11,16.htm
A11: AZN | B11: Astrazeneca | C11: {=xlookup(B11, sectors!A:A, sectors!A:A)} -> AstraZeneca | D11: =left(E11, 3) -> AZN | E11: AZN.L | F11: {=xlookup(A11, sectors!B:B, sectors!C:C)} -> Healthcare & Pharmaceutical | G11: {=XLOOKUP(A11, sectors!B:B, sectors!E:E)} -> Pharmaceuticals & Biotechnology | H11: AstraZeneca is a British-Swedish multinational pharmaceutical and biotechnology company with its headquarters in Cambridge, England. | I11: 02723534 | J11: ="https://find-and-update.company-information.service.gov.uk/company/"&$I11 -> https://find-and-update.company-information.service.gov.uk/company/02723534 | K11: astrazeneca | L11: AstraZeneca | M11: https://www.glassdoor.co.uk/Overview/Working-at-AstraZeneca-EI_IE9214.11,22.htm
A12: BA. | B12: BAE Systems | C12: {=xlookup(B12, sectors!A:A, sectors!A:A)} -> BAE Systems | D12: =left(E12, 3) -> BA. | E12: BA.L | F12: {=xlookup(A12, sectors!B:B, sectors!C:C)} -> Engineering & Construction | G12: {=XLOOKUP(A12, sectors!B:B, sectors!E:E)} -> Aerospace & Defence | H12: BAE Systems is a British multinational arms, security, and aerospace company based in London, England. It is the largest defence contractor in Europe, and ranked the seventh-largest in the world based. | I12: 01470151 | J12: ="https://find-and-update.company-information.service.gov.uk/company/"&$I12 -> https://find-and-update.company-information.service.gov.uk/company/01470151 | K12: bae systems | L12: BAE Systems | M12: https://www.glassdoor.co.uk/Overview/Working-at-BAE-Systems-EI_IE1653490.11,22.htm
A13: BARC | B13: Barclays | C13: {=xlookup(B13, sectors!A:A, sectors!A:A)} -> Barclays | D13: BARC | E13: BARC.L | F13: {=xlookup(A13, sectors!B:B, sectors!C:C)} -> Financial Services | G13: {=XLOOKUP(A13, sectors!B:B, sectors!E:E)} -> Banks | H13: Barclays is a British multinational universal bank, providing consumer banking services, as well as being a global corporate and investment bank. | I13: 00048839 | J13: ="https://find-and-update.company-information.service.gov.uk/company/"&$I13 -> https://find-and-update.company-information.service.gov.uk/company/00048839 | K13: barclays | L13: Barclays | M13: https://www.glassdoor.co.uk/Overview/Working-at-Barclays-EI_IE3456.11,19.htm
A14: BATS | B14: British American Tobacco | C14: {=xlookup(B14, sectors!A:A, sectors!A:A)} -> British American Tobacco | D14: BATS | E14: BATS.L | F14: {=xlookup(A14, sectors!B:B, sectors!C:C)} -> Tobacco | G14: {=XLOOKUP(A14, sectors!B:B, sectors!E:E)} -> Tobacco | H14: British American Tobacco is a British multinational company that manufactures and sells cigarettes, tobacco and other nicotine products. | I14: 03407696 | J14: ="https://find-and-update.company-information.service.gov.uk/company/"&$I14 -> https://find-and-update.company-information.service.gov.uk/company/03407696 | K14: british american tobacco | L14: British American Tobacco | M14: https://www.glassdoor.co.uk/Overview/Working-at-British-American-Tobacco-EI_IE8378.11,35.htm
A15: BDEV | B15: Barratt Developments | C15: {=xlookup(B15, sectors!A:A, sectors!A:A)} -> Barratt Developments | D15: BDEV | E15: BDEV.L | F15: {=xlookup(A15, sectors!B:B, sectors!C:C)} -> Engineering & Construction | G15: {=XLOOKUP(A15, sectors!B:B, sectors!E:E)} -> Household Goods & Home Construction | H15: Barratt Developments is one of the largest residential property development and construction companies in the United Kingdom operating across England, Wales and Scotland. | I15: 00604574 | J15: ="https://find-and-update.company-information.service.gov.uk/company/"&$I15 -> https://find-and-update.company-information.service.gov.uk/company/00604574 | K15: barratt developments | M15: https://www.glassdoor.co.uk/Overview/Working-at-Barratt-Developments-EI_IE10844.11,31.htm
A16: BEZ | B16: Beazley | C16: Beazley Group | D16: =left(E16, 3) -> BEZ | E16: BEZ.L | F16: {=xlookup(A16, sectors!B:B, sectors!C:C)} -> Financial Services | G16: {=XLOOKUP(A16, sectors!B:B, sectors!E:E)} -> Insurance | H16: Beazley is the British parent company of specialist insurance businesses with operations in Europe, the US, and Asia. it is a Lloyds of London insurer, specialising in writing specialty-risk insurance and reinsurance business. | I16: 09763575 | J16: ="https://find-and-update.company-information.service.gov.uk/company/"&$I16 -> https://find-and-update.company-information.service.gov.uk/company/09763575 | K16: beazley | M16: https://www.glassdoor.co.uk/Overview/Working-at-Beazley-Group-EI_IE24586.11,24.htm
A17: BKG | B17: Berkeley Group Holdings | C17: {=xlookup(B17, sectors!A:A, sectors!A:A)} -> Berkeley Group Holdings | D17: =left(E17, 3) -> BKG | E17: BKG.L | F17: {=xlookup(A17, sectors!B:B, sectors!C:C)} -> Engineering & Construction | G17: {=XLOOKUP(A17, sectors!B:B, sectors!E:E)} -> Household Goods & Home Construction | H17: Berkeley Group Holdings is a British property developer and house-builder based in Cobham, England. | I17: 05172586 | J17: ="https://find-and-update.company-information.service.gov.uk/company/"&$I17 -> https://find-and-update.company-information.service.gov.uk/company/05172586 | K17: berkeley group | M17: https://www.glassdoor.co.uk/Overview/Working-at-Berkeley-Group-EI_IE10118.11,25.htm
A18: BLND | B18: British Land Co | C18: British Land | D18: BLND | E18: BLND.L | F18: {=xlookup(A18, sectors!B:B, sectors!C:C)} -> Real Estate | G18: {=XLOOKUP(A18, sectors!B:B, sectors!E:E)} -> Real Estate Investment Trusts | H18: British Land is a property company which creates, owns and manages UK real estate. It is one of the largest property development and investment companies in the United Kingdom. | I18: 00621920 | J18: ="https://find-and-update.company-information.service.gov.uk/company/"&$I18 -> https://find-and-update.company-information.service.gov.uk/company/00621920 | K18: british land | M18: https://www.glassdoor.co.uk/Overview/Working-at-British-Land-Company-EI_IE10847.11,31.htm
A19: BME | B19: B&M | C19: B&M European Value Retail S.A. | D19: =left(E19, 3) -> BME | E19: BME.L | F19: {=xlookup(A19, sectors!B:B, sectors!C:C)} -> Retail & Services | G19: {=XLOOKUP(A19, sectors!B:B, sectors!E:E)} -> Retailers | H19: B&M is a British multinational variety store chain founded in 1978 and incorporated in Luxembourg. | I19: 08309974 | J19: ="https://find-and-update.company-information.service.gov.uk/company/"&$I19 -> https://find-and-update.company-information.service.gov.uk/company/08309974 | K19: b&m | M19: https://www.glassdoor.co.uk/Overview/Working-at-B-and-M-Retail-EI_IE629657.11,25.htm
A20: BNZL | B20: Bunzl | C20: {=xlookup(B20, sectors!A:A, sectors!A:A)} -> Bunzl | D20: BNZL | E20: BNZL.L | F20: {=xlookup(A20, sectors!B:B, sectors!C:C)} -> Retail & Services | G20: {=XLOOKUP(A20, sectors!B:B, sectors!E:E)} -> Support Services | H20: Bunzl plc is a British multinational distribution and outsourcing company headquartered in London, England. | I20: 00358948 | J20: ="https://find-and-update.company-information.service.gov.uk/company/"&$I20 -> https://find-and-update.company-information.service.gov.uk/company/00358948 | K20: bunzl | M20: https://www.glassdoor.co.uk/Overview/Working-at-Bunzl-EI_IE10133.11,16.htm
A21: BP. | B21: BP | C21: {=xlookup(B21, sectors!A:A, sectors!A:A)} -> BP | D21: =left(E21, 3) -> BP. | E21: BP.L | F21: {=xlookup(A21, sectors!B:B, sectors!C:C)} -> Mining & Extraction | G21: {=XLOOKUP(A21, sectors!B:B, sectors!E:E)} -> Oil & Gas Producers | H21: BP is a British multinational oil and gas company headquartered in London, England. It is one the world's largest companies measured by revenues and profits. | I21: 00102498 | J21: ="https://find-and-update.company-information.service.gov.uk/company/"&$I21 -> https://find-and-update.company-information.service.gov.uk/company/00102498 | K21: bp | L21: BP | M21: https://www.glassdoor.co.uk/Overview/Working-at-BP-EI_IE9011.11,13.htm
A22: BRBY | B22: Burberry | C22: Burberry Group | D22: BRBY | E22: BRBY.L | F22: {=xlookup(A22, sectors!B:B, sectors!C:C)} -> Retail & Services | G22: {=XLOOKUP(A22, sectors!B:B, sectors!E:E)} -> Personal Goods | H22: Burberry Group is a British luxury fashion house that designs and distributes ready to wear, including trench coats, leather accessories, and footwear. | I22: 03458224 | J22: ="https://find-and-update.company-information.service.gov.uk/company/"&$I22 -> https://find-and-update.company-information.service.gov.uk/company/03458224 | K22: burberry | L22: Burberry | M22: https://www.glassdoor.co.uk/Overview/Working-at-Burberry-EI_IE13011.11,19.htm
A23: BT.A | B23: BT Group | C23: {=xlookup(B23, sectors!A:A, sectors!A:A)} -> BT Group | D23: BT.A | E23: BT-A.L | F23: {=xlookup(A23, sectors!B:B, sectors!C:C)} -> Retail & Services | G23: {=XLOOKUP(A23, sectors!B:B, sectors!E:E)} -> Fixed Line Telecommunications | H23: BT Group is a British multinational telecommunications holding company headquartered in London, England. It has operations in around 180 countries and is the largest provider of fixed-line, broadband and mobile services in the UK, and also provides subscription television and IT services. | I23: 04190816 | J23: ="https://find-and-update.company-information.service.gov.uk/company/"&$I23 -> https://find-and-update.company-information.service.gov.uk/company/04190816 | K23: bt, openreach | L23: BT | M23: https://www.glassdoor.co.uk/Overview/Working-at-BT-EI_IE3463.11,13.htm
A24: CCH | B24: Coca-Cola HBC | C24: Coca-Cola Hbc Ag | D24: =left(E24, 3) -> CCH | E24: CCH.L | F24: {=xlookup(A24, sectors!B:B, sectors!C:C)} -> Food & Beverage | G24: {=XLOOKUP(A24, sectors!B:B, sectors!E:E)} -> Beverages | H24: Coca-Cola HBC AG also known as Coca-Cola Hellenic Bottling Company or just Coca-Cola Hellenic is the world's third-largest Coca-Cola anchor bottler in terms of volume with sales of more than 2 billion unit cases. | I24: n/a | K24: coca-cola hbc, coca-cola hellenic | M24: https://www.glassdoor.co.uk/Overview/Working-at-Coca-Cola-HBC-EI_IE10550.11,24.htm
A25: CNA | B25: Centrica | C25: {=xlookup(B25, sectors!A:A, sectors!A:A)} -> Centrica | D25: =left(E25, 3) -> CNA | E25: CNA.L | F25: {=xlookup(A25, sectors!B:B, sectors!C:C)} -> Engineering & Construction | G25: {=XLOOKUP(A25, sectors!B:B, sectors!E:E)} -> Utilities | H25: Centrica plc is a British multinational energy and services company. Its principal activity is the supply of electricity and gas to consumers in the United Kingdom and Ireland. | I25: 03033654 | J25: ="https://find-and-update.company-information.service.gov.uk/company/"&$I25 -> https://find-and-update.company-information.service.gov.uk/company/03033654 | K25: centrica | M25: https://www.glassdoor.co.uk/Overview/Working-at-Centrica-EI_IE6731.11,19.htm
A26: CPG | B26: Compass Group | C26: {=xlookup(B26, sectors!A:A, sectors!A:A)} -> Compass Group | D26: =left(E26, 3) -> CPG | E26: CPG.L | F26: {=xlookup(A26, sectors!B:B, sectors!C:C)} -> Hospitality | G26: {=XLOOKUP(A26, sectors!B:B, sectors!E:E)} -> Support Services | H26: Compass Group plc is a British multinational contract foodservice company. It is the largest contract foodservice company in Europe, ahead of Sodexo, employing over 500,000 people. | I26: 04083914 | J26: ="https://find-and-update.company-information.service.gov.uk/company/"&$I26 -> https://find-and-update.company-information.service.gov.uk/company/04083914 | K26: compass | L26: Compass Group | M26: https://www.glassdoor.co.uk/Overview/Working-at-Compass-Group-EI_IE10832.11,24.htm
A27: CRDA | B27: Croda International | C27: {=xlookup(B27, sectors!A:A, sectors!A:A)} -> Croda International | D27: CRDA | E27: CRDA.L | F27: {=xlookup(A27, sectors!B:B, sectors!C:C)} -> Engineering & Construction | G27: {=XLOOKUP(A27, sectors!B:B, sectors!E:E)} -> Chemicals | H27: Croda International plc is a British speciality chemicals company. | I27: 00206132 | J27: ="https://find-and-update.company-information.service.gov.uk/company/"&$I27 -> https://find-and-update.company-information.service.gov.uk/company/00206132 | K27: croda | M27: https://www.glassdoor.co.uk/Overview/Working-at-Croda-EI_IE10140.11,16.htm
A28: CRH | B28: CRH | C28: CRH plc | D28: =left(E28, 3) -> CRH | E28: CRH.L | F28: {=xlookup(A28, sectors!B:B, sectors!C:C)} -> Engineering & Construction | G28: {=XLOOKUP(A28, sectors!B:B, sectors!E:E)} -> Construction & Materials | H28: CRH plc is an international group of diversified building materials businesses. It manufactures and supplies a wide range of products for the construction industry. | I28: n/a | K28: crh | L28: CRH PLC | M28: https://www.glassdoor.co.uk/Overview/Working-at-CRH-EI_IE10480.11,14.htm
